Workbook

Sheet Base General OR_Inicial
A1: N° | B1: DEPARTAMENTO | C1: MUNICIPIO | D1: VALOR | E1: N° CE | F1: USUARIOS | G1: Potencia (mWp) | H1: Potencia ((kWp) | I1: Fecha Inicial | J1: OR/Generador | K1: TIPO DE PROYECTO | L1: ZONA
A2: 1 | B2: AMAZONAS | C2: AMAZONAS | D2: 53908378733 | E2: 23 | F2: 1367 | G2: 2.02 | H2: 2020 | I2: 46295 | J2: ENAM | K2: CENTRALIZADO | L2: ZNI | N2: =G2*1000 -> 2020
A3: 2 | B3: CAQUETA | C3: CARTAGENA DEL CHAIIRA | D3: 24437339433 | E3: 69 | F3: 755 | G3: 1.52 | H3: 1520 | I3: 46223 | J3: GENSA | K3: INDIVIDUALES | L3: ZNI | N3: =G3*1000 -> 1520
A4: 3 | B4: CESAR | C4: BECERRIL | D4: 18447808737 | E4: 57 | F4: 623 | G4: 0.76 | H4: 760 | I4: 46162 | J4: ELECTROCAQUETA | K4: INDIVUDUALES | L4: ZNI | N4: =G4*1000 -> 760
A5: 4 | B5: CESAR | C5: CURUMANI | D5: 18114661005 | E5: 57 | F5: 624 | G5: 0.76 | H5: 760 | I5: 46162 | J5: ELECTROCAQUETA | K5: INDIVUDUALES | L5: ZNI | N5: =G5*1000 -> 760
A6: 5 | B6: CHOCO | C6: NUQUI | D6: 79316865070 | E6: 34 | F6: 2036 | G6: 4 | H6: 4000 | I6: 46234 | J6: DISPAC | K6: CENTRALIZADO | L6: ZNI | N6: =G6*1000 -> 4000
A7: 6 | B7: CHOCO | C7: BAHIA SOLANO | D7: 83008042889 | E7: 38 | F7: 2295 | G7: 3 | H7: 3000 | I7: 46223 | J7: GENSA | K7: CENTRALIZADO | L7: ZNI | N7: =G7*1000 -> 3000
A8: 7 | B8: LA GUAJIRA | C8: MAICAO Y ALBANIA | D8: 322709746890 | E8: 969 | F8: 10664 | G8: 11.73 | H8: 11730 | I8: 46234 | J8: DISPAC | K8: INDIVIDUALES | L8: ZNI | N8: =G8*1000 -> 11730
A9: 8 | B9: LA GUAJIRA | C9: URIBIA | D9: 30713269905 | E9: 91 | F9: 1000 | G9: 1.2 | H9: 1200 | I9: 46223 | J9: GENSA | K9: INDIVIDUALES | L9: ZNI | N9: =G9*1000 -> 1200
A10: 9 | B10: MAGDALENA | C10: SANTA MARTA | D10: 51087244522 | E10: 144 | F10: 1581 | G10: 1.74 | H10: 1740 | I10: 46193 | J10: ELECTROCAQUETA | K10: INDIVIDUALES | L10: ZNI | N10: =G10*1000 -> 1740
A11: 10 | B11: META | C11: LA URIBE | D11: 31420264769 | E11: 91 | F11: 1003 | G11: 1.21 | H11: 1210 | I11: 46223 | J11: GENSA | K11: INDIVIDUALES | L11: ZNI | N11: =G11*1000 -> 1210
A12: 11 | B12: NARIÑO | C12: RICAURTE | D12: 27742028640 | E12: 78 | F12: 862 | G12: 0.95 | H12: 950 | I12: 46193 | J12: ELECTROCAQUETA | K12: INDIVIDUALES | L12: ZNI | N12: =G12*1000 -> 950
A13: 12 | B13: NORTE DE SANTANDER | C13: TEORAMA EL CARMEN CONVENCIÓN HACARI SAN CALIXTO TIBU | D13: 121589085878 | E13: 344 | F13: 3783 | G13: 4.16 | H13: 4160 | I13: 46193 | J13: ELECTROCAQUETA | K13: INDIVIDUALES | L13: ZNI | N13: =G13*1000 -> 4160
... A19: 18 | B19: SANTANDER | C19: GUACA | D19: 4402514558 | E19: 14 | F19: 154 | G19: 0.19 | H19: 190 | I19: 46193 | J19: ELECTROCAQUETA | K19: INDIVIDUALES | L19: ZNI | N19: =G19*1000 -> 190
A20: TOTAL | D20: =+SUM(D2:D19) -> 968268668130 | E20: =+SUM(E2:E19) -> 2297 | F20: =+SUM(F2:F19) -> 29911 | G20: =+SUM(G2:G19) -> 37.06 | H20: =SUM(H2:H19) -> 37060

Sheet Gráficas_General
J1: Potencia Total | K1: 760
C2: OPERADOR | E2: Electrocaqueta | J2: Usuarios Totales | K2: 623 | L2: =5*30 -> 150 | P2: OPERADOR | R2: Dispac
C3: POTENCIA TOTAL | E3: 9,83 MWp | P3: POTENCIA TOTAL | R3: 11,73 MWp
C4: USUARIOS TOTALES | E4: 8785 | P4: USUARIOS TOTALES | R4: 10664
C7: Mes | D7: Usuarios (Plan Inicial) | E7: Usuarios (Nueva Estrat.) | F7: Usuarios Acum. (Inicial) | G7: Usuarios Acum. (Nueva) | H7: Potencia kW (Plan Inicial) | I7: Potencia kW (Nueva Estrat.) | J7: Potencia Acum. (Inicial) | K7: Potencia Acum. (Nueva) | L7: Usuarios Ejcutado | M7: Usuarios Ejcutado Acumulado | P7: Mes | Q7: Usuarios (Plan Inicial) | R7: Usuarios (Nueva Estrat.) | S7: Usuarios Acum. (Inicial) | T7: Usuarios Acum. (Nueva) | U7: Potencia kW (Plan Inicial) | V7: Potencia kW (Nueva Estrat.) | W7: Potencia Acum. (Inicial) | X7: Potencia Acum. (Nueva) | Y7: Usuarios Ejcutado | Z7: Usuarios Ejcutado Acumulado
C8: 46117 | D8: 0 | E8: 0 | F8: 0 | G8: 0 | L8: 0 | M8: =L8 -> 0 | P8: 46117 | Q8: 0 | R8: 0 | S8: 0 | T8: 0 | Y8: 0 | Z8: =Y8 -> 0
C9: 46122 | D9: 0 | E9: 0 | F9: 0 | G9: 0 | L9: 0 | M9: =M8+L9 -> 0 | P9: 46122 | Q9: 0 | R9: 0 | S9: 0 | T9: 0 | Y9: 0 | Z9: =Z8+Y9 -> 0
C10: 46127 | D10: 0 | E10: 0 | F10: 0 | G10: 0 | L10: 0 | M10: =M9+L10 -> 0 | P10: 46127 | Q10: 0 | R10: 0 | S10: 0 | T10: 0 | Y10: 0 | Z10: =Z9+Y10 -> 0
C11: 46132 | D11: 0 | E11: 0 | F11: 0 | G11: 0 | L11: 0 | M11: =M10+L11 -> 0 | P11: 46132 | Q11: 0 | R11: 0 | S11: 0 | T11: 0 | Y11: 0 | Z11: =Z10+Y11 -> 0
C12: 46137 | D12: 0 | E12: 0 | F12: 0 | G12: 0 | L12: 0 | M12: =M11+L12 -> 0 | P12: 46137 | Q12: 0 | R12: 0 | S12: 0 | T12: 0 | Y12: 0 | Z12: =Z11+Y12 -> 0
C13: 46142 | D13: 0 | E13: 0 | F13: 0 | G13: 0 | L13: 0 | M13: =M12+L13 -> 0 | P13: 46142 | Q13: 0 | R13: 0 | S13: 0 | T13: 0 | Y13: 0 | Z13: =Z12+Y13 -> 0
C14: 46147 | D14: 0 | E14: 250 | F14: =D14 -> 0 | G14: =E14 -> 250 | H14: =$K$1/$K$2*D14 -> 0 | I14: =$K$1/$K$2*E14 -> 304.97592 | J14: =H14 -> 0 | K14: =I14 -> 304.97592 | L14: 0 | M14: =M13+L14 -> 0 | P14: 46147 | Q14: 0 | R14: 0 | S14: =Q14 -> 0 | T14: =R14 -> 0 | U14: =$K$1/$K$2*Q14 -> 0 | V14: =$K$1/$K$2*R14 -> 0 | W14: =U14 -> 0 | X14: =V14 -> 0 | Y14: 0 | Z14: =Z13+Y14 -> 0
C15: 46152 | D15: 0 | E15: 135 | F15: =F14+D15 -> 0 | G15: =G14+E15 -> 385 | H15: =$K$1/$K$2*D15 -> 0 | I15: =$K$1/$K$2*E15 -> 164.687 | J15: =J14+H15 -> 0 | K15: =K14+I15 -> 469.66292 | L15: 55 | M15: =M14+L15 -> 55 | P15: 46152 | Q15: 0 | R15: 0 | S15: =S14+Q15 -> 0 | T15: =T14+R15 -> 0 | U15: =$K$1/$K$2*Q15 -> 0 | V15: =$K$1/$K$2*R15 -> 0 | W15: =W14+U15 -> 0 | X15: =X14+V15 -> 0 | Y15: 0 | Z15: =Z14+Y15 -> 0
C16: 46157 | D16: 0 | E16: 260 | F16: =F15+D16 -> 0 | G16: =G15+E16 -> 645 | H16: =$K$1/$K$2*D16 -> 0 | I16: =$K$1/$K$2*E16 -> 317.17496 | J16: =J15+H16 -> 0 | K16: =K15+I16 -> 786.83788 | L16: 55 | M16: =M15+L16 -> 110 | P16: 46157 | Q16: 0 | R16: 80 | S16: =S15+Q16 -> 0 | T16: =T15+R16 -> 80 | U16: =$K$1/$K$2*Q16 -> 0 | V16: =$K$1/$K$2*R16 -> 97.592295 | W16: =W15+U16 -> 0 | X16: =X15+V16 -> 97.592295 | Y16: 0 | Z16: =Z15+Y16 -> 0
C17: 46162 | D17: 0 | E17: 255 | F17: =F16+D17 -> 0 | G17: =G16+E17 -> 900 | H17: =$K$1/$K$2*D17 -> 0 | I17: =$K$1/$K$2*E17 -> 311.07544 | J17: =J16+H17 -> 0 | K17: =K16+I17 -> 1097.9133 | L17: 55 | M17: =M16+L17 -> 165 | P17: 46162 | Q17: 0 | R17: 160 | S17: =S16+Q17 -> 0 | T17: =T16+R17 -> 240 | U17: =$K$1/$K$2*Q17 -> 0 | V17: =$K$1/$K$2*R17 -> 195.18459 | W17: =W16+U17 -> 0 | X17: =X16+V17 -> 292.77689 | Y17: 80 | Z17: =Z16+Y17 -> 80
C18: 46167 | D18: 0 | E18: 150 | F18: =F17+D18 -> 0 | G18: =G17+E18 -> 1050 | H18: =$K$1/$K$2*D18 -> 0 | I18: =$K$1/$K$2*E18 -> 182.98555 | J18: =J17+H18 -> 0 | K18: =K17+I18 -> 1280.8989 | L18: 71 | M18: =M17+L18 -> 236 | P18: 46167 | Q18: 0 | R18: 160 | S18: =S17+Q18 -> 0 | T18: =T17+R18 -> 400 | U18: =$K$1/$K$2*Q18 -> 0 | V18: =$K$1/$K$2*R18 -> 195.18459 | W18: =W17+U18 -> 0 | X18: =X17+V18 -> 487.96148 | Y18: 160 | Z18: =Z17+Y18 -> 240
C19: 46172 | D19: 0 | E19: 110 | F19: =F18+D19 -> 0 | G19: =G18+E19 -> 1160 | H19: =$K$1/$K$2*D19 -> 0 | I19: =$K$1/$K$2*E19 -> 134.18941 | J19: =J18+H19 -> 0 | K19: =K18+I19 -> 1415.0883 | L19: 280 | M19: =M18+L19 -> 516 | P19: 46172 | Q19: 0 | R19: 80 | S19: =S18+Q19 -> 0 | T19: =T18+R19 -> 480 | U19: =$K$1/$K$2*Q19 -> 0 | V19: =$K$1/$K$2*R19 -> 97.592295 | W19: =W18+U19 -> 0 | X19: =X18+V19 -> 585.55377 | Y19: 160 | Z19: =Z18+Y19 -> 400
C20: 46177 | D20: 250 | E20: 300 | F20: =F19+D20 -> 250 | G20: =G19+E20 -> 1460 | H20: =$K$1/$K$2*D20 -> 304.97592 | I20: =$K$1/$K$2*E20 -> 365.97111 | J20: =J19+H20 -> 304.97592 | K20: =K19+I20 -> 1781.0594 | L20: 380 | M20: =M19+L20 -> 896 | P20: 46177 | Q20: 0 | R20: 80 | S20: =S19+Q20 -> 0 | T20: =T19+R20 -> 560 | U20: =$K$1/$K$2*Q20 -> 0 | V20: =$K$1/$K$2*R20 -> 97.592295 | W20: =W19+U20 -> 0 | X20: =X19+V20 -> 683.14607 | Y20: 80 | Z20: =Z19+Y20 -> 480
C21: 46182 | D21: 135 | E21: 463 | F21: =F20+D21 -> 385 | G21: =G20+E21 -> 1923 | H21: =$K$1/$K$2*D21 -> 164.687 | I21: =$K$1/$K$2*E21 -> 564.81541 | J21: =J20+H21 -> 469.66292 | L21: 270 | M21: =M20+L21 -> 1166 | P21: 46182 | Q21: 0 | R21: 80 | S21: =S20+Q21 -> 0 | T21: =T20+R21 -> 640 | U21: =$K$1/$K$2*Q21 -> 0 | V21: =$K$1/$K$2*R21 -> 97.592295 | W21: =W20+U21 -> 0 | Y21: 80 | Z21: =Z20+Y21 -> 560
C22: 46187 | D22: 260 | E22: 84 | F22: =F21+D22 -> 645 | G22: =G21+E22 -> 2007 | H22: =$K$1/$K$2*D22 -> 317.17496 | I22: =$K$1/$K$2*E22 -> 102.47191 | J22: =J21+H22 -> 786.83788 | L22: 174 | M22: =M21+L22 -> 1340 | P22: 46187 | Q22: 0 | R22: 80 | S22: =S21+Q22 -> 0 | T22: =T21+R22 -> 720 | U22: =$K$1/$K$2*Q22 -> 0 | V22: =$K$1/$K$2*R22 -> 97.592295 | W22: =W21+U22 -> 0 | Y22: 80 | Z22: =Z21+Y22 -> 640
C23: 46192 | D23: 255 | E23: 263 | F23: =F22+D23 -> 900 | G23: =G22+E23 -> 2270 | H23: =$K$1/$K$2*D23 -> 311.07544 | I23: =$K$1/$K$2*E23 -> 320.83467 | P23: 46192 | Q23: 400 | R23: 300 | S23: =S22+Q23 -> 400 | T23: =T22+R23 -> 1020 | U23: =$K$1/$K$2*Q23 -> 487.96148 | V23: =$K$1/$K$2*R23 -> 365.97111 | Y23: 80 | Z23: =Z22+Y23 -> 720
C24: 46197 | D24: 150 | E24: 230 | F24: =F23+D24 -> 1050 | G24: =G23+E24 -> 2500 | H24: =$K$1/$K$2*D24 -> 182.98555 | I24: =$K$1/$K$2*E24 -> 280.57785 | P24: 46197 | Q24: 400 | R24: 300 | S24: =S23+Q24 -> 800 | T24: =T23+R24 -> 1320 | U24: =$K$1/$K$2*Q24 -> 487.96148 | V24: =$K$1/$K$2*R24 -> 365.97111
C25: 46202 | D25: 110 | E25: 245 | F25: =F24+D25 -> 1160 | G25: =G24+E25 -> 2745 | H25: =$K$1/$K$2*D25 -> 134.18941 | I25: =$K$1/$K$2*E25 -> 298.8764 | P25: 46202 | Q25: 400 | R25: 300 | S25: =S24+Q25 -> 1200 | T25: =T24+R25 -> 1620 | U25: =$K$1/$K$2*Q25 -> 487.96148 | V25: =$K$1/$K$2*R25 -> 365.97111
C26: 46207 | D26: 300 | E26: 695 | F26: =F25+D26 -> 1460 | G26: =G25+E26 -> 3440 | H26: =$K$1/$K$2*D26 -> 365.97111 | P26: 46207 | Q26: 400 | R26: 300 | S26: =S25+Q26 -> 1600 | T26: =T25+R26 -> 1920 | U26: =$K$1/$K$2*Q26 -> 487.96148
C27: 46212 | D27: 463 | E27: 555 | F27: =F26+D27 -> 1923 | G27: =G26+E27 -> 3995 | H27: =$K$1/$K$2*D27 -> 564.81541 | P27: 46212 | Q27: 400 | R27: 300 | S27: =S26+Q27 -> 2000 | T27: =T26+R27 -> 2220 | U27: =$K$1/$K$2*Q27 -> 487.96148
C28: 46217 | D28: 84 | E28: 565 | F28: =F27+D28 -> 2007 | G28: =G27+E28 -> 4560 | P28: 46217 | Q28: 400 | R28: 300 | S28: =S27+Q28 -> 2400 | T28: =T27+R28 -> 2520
C29: 46222 | D29: 263 | E29: 870 | F29: =F28+D29 -> 2270 | G29: =G28+E29 -> 5430 | P29: 46222 | Q29: 400 | R29: 500 | S29: =S28+Q29 -> 2800 | T29: =T28+R29 -> 3020
C30: 46227 | D30: 230 | E30: 438 | F30: =F29+D30 -> 2500 | G30: =G29+E30 -> 5868 | P30: 46227 | Q30: 400 | R30: 500 | S30: =S29+Q30 -> 3200 | T30: =T29+R30 -> 3520
C31: 46232 | D31: 245 | E31: 438 | F31: =F30+D31 -> 2745 | G31: =G30+E31 -> 6306 | P31: 46232 | Q31: 400 | R31: 700 | S31: =S30+Q31 -> 3600 | T31: =T30+R31 -> 4220
C32: 46237 | D32: 695 | E32: 438 | F32: =F31+D32 -> 3440 | G32: =G31+E32 -> 6744 | P32: 46237 | Q32: 400 | R32: 700 | S32: =S31+Q32 -> 4000 | T32: =T31+R32 -> 4920
C33: 46242 | D33: 555 | E33: 438 | F33: =F32+D33 -> 3995 | G33: =G32+E33 -> 7182 | P33: 46242 | Q33: 400 | R33: 700 | S33: =S32+Q33 -> 4400 | T33: =T32+R33 -> 5620
C34: 46247 | D34: 565 | E34: 438 | F34: =F33+D34 -> 4560 | G34: =G33+E34 -> 7620 | P34: 46247 | Q34: 400 | R34: 700 | S34: =S33+Q34 -> 4800 | T34: =T33+R34 -> 6320
C35: 46252 | D35: 870 | E35: 1165 | F35: =F34+D35 -> 5430 | G35: =G34+E35 -> 8785 | P35: 46252 | Q35: 400 | R35: 700 | S35: =S34+Q35 -> 5200 | T35: =T34+R35 -> 7020
C36: 46257 | D36: 438 | F36: =F35+D36 -> 5868 | P36: 46257 | Q36: 400 | R36: 700 | S36: =S35+Q36 -> 5600 | T36: =T35+R36 -> 7720
C37: 46262 | D37: 438 | F37: =F36+D37 -> 6306 | P37: 46262 | Q37: 400 | R37: 700 | S37: =S36+Q37 -> 6000 | T37: =T36+R37 -> 8420
C38: 46267 | D38: 438 | F38: =F37+D38 -> 6744 | P38: 46267 | Q38: 600 | R38: 720 | S38: =S37+Q38 -> 6600 | T38: =T37+R38 -> 9140
C39: 46272 | D39: 438 | F39: =F38+D39 -> 7182 | P39: 46272 | Q39: 800 | R39: 700 | S39: =S38+Q39 -> 7400 | T39: =T38+R39 -> 9840
C40: 46277 | D40: 438 | F40: =F39+D40 -> 7620 | P40: 46277 | Q40: 800 | R40: 824 | S40: =S39+Q40 -> 8200 | T40: =T39+R40 -> 10664
C41: 46282 | D41: 438 | F41: =F40+D41 -> 8058 | P41: 46282 | Q41: 800 | S41: =S40+Q41 -> 9000
C42: 46287 | D42: 438 | F42: =F41+D42 -> 8496 | P42: 46287 | Q42: 800 | S42: =S41+Q42 -> 9800
...

Sheet TD 
A1: Operador de Red | B1: (Todas)
A3: Suma de 30/05/2026 | B3: Suma de 04/06/2026 | C3: Suma de 09/06/2026 | D3: Suma de 14/06/2026 | E3: Suma de 20/06/2026 | F3: Suma de 25/06/2026 | G3: Suma de 30/06/2026 | H3: Suma de 05/07/2026 | I3: Suma de 10/07/2026 | J3: Suma de 15/07/2026 | K3: Suma de 20/07/2026 | L3: Suma de 25/07/2026 | M3: Suma de 30/07/2026
A4: 3542 | B4: 4270 | C4: 5383 | D4: 5522 | E4: 5880 | F4: 7105 | G4: 8220 | H4: 10415 | I4: 12815 | J4: 15675 | K4: 18820 | L4: 21578 | M4: 28544

Sheet Base General_OR_Inicial
A1: N° | B1: DEPARTAMENTO | C1: MUNICIPIO | D1: VALOR | E1: N° CE | F1: USUARIOS | G1: Potencia (mWp) | H1: OR/Generador | I1: TIPO DE PROYECTO | J1: ZONA
A2: 1 | B2: AMAZONAS | C2: AMAZONAS | D2: 53908378733 | E2: 23 | F2: 1367 | G2: 2.02 | H2: ENAM | I2: CENTRALIZADO | J2: ZNI
A3: 2 | B3: CAQUETA | C3: CARTAGENA DEL CHAIIRA | D3: 24437339433 | E3: 69 | F3: 755 | G3: 1.52 | H3: GENSA | I3: INDIVIDUALES | J3: ZNI
A4: 3 | B4: CESAR | C4: BECERRIL | D4: 18447808737 | E4: 57 | F4: 623 | G4: 0.76 | H4: ELECTROCAQUETA | I4: INDIVUDUALES | J4: ZNI
A5: 4 | B5: CESAR | C5: CURUMANI | D5: 18114661005 | E5: 57 | F5: 624 | G5: 0.76 | H5: ELECTROCAQUETA | I5: INDIVUDUALES | J5: ZNI
A6: 5 | B6: CHOCO | C6: NUQUI | D6: 79316865070 | E6: 34 | F6: 2036 | G6: 4 | H6: DISPAC | I6: CENTRALIZADO | J6: ZNI
A7: 6 | B7: CHOCO | C7: BAHIA SOLANO | D7: 83008042889 | E7: 38 | F7: 2295 | G7: 3 | H7: GENSA | I7: CENTRALIZADO | J7: ZNI
A8: 7 | B8: LA GUAJIRA | C8: MAICAO Y ALBANIA | D8: 322709746890 | E8: 969 | F8: 10664 | G8: 11.73 | H8: DISPAC | I8: INDIVIDUALES | J8: ZNI
A9: 8 | B9: LA GUAJIRA | C9: URIBIA | D9: 30713269905 | E9: 91 | F9: 1000 | G9: 1.2 | H9: GENSA | I9: INDIVIDUALES | J9: ZNI
A10: 9 | B10: MAGDALENA | C10: SANTA MARTA | D10: 51087244522 | E10: 144 | F10: 1581 | G10: 1.74 | H10: ELECTROCAQUETA | I10: INDIVIDUALES | J10: ZNI
A11: 10 | B11: META | C11: LA URIBE | D11: 31420264769 | E11: 91 | F11: 1003 | G11: 1.21 | H11: GENSA | I11: INDIVIDUALES | J11: ZNI
A12: 11 | B12: NARIÑO | C12: RICAURTE | D12: 27742028640 | E12: 78 | F12: 862 | G12: 0.95 | H12: ELECTROCAQUETA | I12: INDIVIDUALES | J12: ZNI
A13: 12 | B13: NORTE DE SANTANDER | C13: TEORAMA EL CARMEN CONVENCIÓN HACARI SAN CALIXTO TIBU | D13: 121589085878 | E13: 344 | F13: 3783 | G13: 4.16 | H13: ELECTROCAQUETA | I13: INDIVIDUALES | J13: ZNI
... A19: 18 | B19: SANTANDER | C19: GUACA | D19: 4402514558 | E19: 14 | F19: 154 | G19: 0.19 | H19: ELECTROCAQUETA | I19: INDIVIDUALES | J19: ZNI
A20: TOTAL | D20: =+SUM(D2:D19) -> 968268668130 | E20: =+SUM(E2:E19) -> 2297 | F20: =+SUM(F2:F19) -> 29911 | G20: =+SUM(G2:G19) -> 37.06

Sheet Base
C2: CONTRATISTA/ENTIDAD | D2: DEPARTAMENTO | E2: PROYECTO | F2: MUNICIPIO | G2: PROGRAMA | H2: TIPO DE SOLUCIÓN | I2: INVERSIÓN | J2: FECHA | K2: MES | L2: PLANEADO (USUARIOS) | M2: EJECUTADO (USUARIOS) | N2: CAPACIDAD (kWp) (PLANEADA) | O2: CAPACIDAD (kWp) (EJECUTADA) | P2: EFICIENCIA
B3: 18447808737 | C3: Electrocaqueta | D3: Cesar | E3: Becerril | F3: Becerril | G3: Comunidades Energéticas OR | H3: Individual | I3: =$B$3/623*L3 -> 5.92225e+09 | J3: 46162 | K3: Mayo | L3: 200 | M3: ='Seguimiento Diario'!E4 -> 180 | N3: =760/623*L3 -> 243.98074 | O3: =N3/L3*M3 -> 219.58266 | P3: =M3/L3 -> 0.9
B4: 18447808737 | C4: Electrocaqueta | D4: Cesar | E4: Becerril | F4: Becerril | G4: Comunidades Energéticas OR | H4: Individual | I4: =$B$3/623*L4 -> 5.92225e+09 | J4: 46184 | K4: Junio | L4: 200 | M4: ='Seguimiento Diario'!F4 -> 0 | N4: =760/623*L4 -> 243.98074 | O4: =N4/L4*M4 -> 0 | P4: =M4/L4 -> 0
C5: Electrocaqueta | D5: Cesar | E5: Becerril | F5: Becerril | G5: Comunidades Energéticas OR | H5: Individual | I5: =$B$3/623*L5 -> 6.6033087e+09 | J5: 46228 | K5: Julio | L5: 223 | M5: ='Seguimiento Diario'!G4 -> 0 | N5: =760/623*L5 -> 272.03852 | O5: =N5/L5*M5 -> 0 | P5: =M5/L5 -> 0
B6: 18114661005 | C6: Electrocaqueta | D6: Cesar | E6: Curumaní | F6: Curumaní | G6: Comunidades Energéticas OR | H6: Individual | I6: =($B$6/624)*L6 -> 2.9029905e+09 | J6: 46162 | K6: Mayo | L6: 100 | M6: ='Seguimiento Diario'!E5 -> 0 | N6: =(760/624)*L6 -> 121.79487 | O6: =N6/L6*M6 -> 0 | P6: =M6/L6 -> 0
C7: Electrocaqueta | D7: Cesar | E7: Curumaní | F7: Curumaní | G7: Comunidades Energéticas OR | H7: Individual | I7: =($B$6/624)*L7 -> 4.3544858e+09 | J7: 46184 | K7: Junio | L7: 150 | M7: ='Seguimiento Diario'!F5 -> 0 | N7: =(760/624)*L7 -> 182.69231 | O7: =N7/L7*M7 -> 0 | P7: =M7/L7 -> 0
C8: Electrocaqueta | D8: Cesar | E8: Curumaní | F8: Curumaní | G8: Comunidades Energéticas OR | H8: Individual | I8: =($B$6/624)*L8 -> 1.0857185e+10 | J8: 46228 | K8: Julio | L8: =624-(L6+L7) -> 374 | M8: ='Seguimiento Diario'!G5 -> 0 | N8: =(760/624)*L8 -> 455.51282 | O8: =N8/L8*M8 -> 0 | P8: =M8/L8 -> 0
B9: 51087244522 | C9: Electrocaqueta | D9: Magdalena | E9: Santa Marta | F9: Santa Marta | G9: Comunidades Energéticas OR | H9: Individual | I9: =$B$9/1581*L9 -> 1.6156624e+10 | J9: 46184 | K9: Junio | L9: 500 | M9: ='Seguimiento Diario'!F6 -> 0 | N9: =1740/1581*L9 -> 550.28463 | O9: =N9/L9*M9 -> 0 | P9: =M9/L9 -> 0
C10: Electrocaqueta | D10: Magdalena | E10: Santa Marta | F10: Santa Marta | G10: Comunidades Energéticas OR | H10: Individual | I10: =$B$9/1581*L10 -> 3.4930621e+10 | J10: 46228 | K10: Julio | L10: =1581-L9 -> 1081 | M10: ='Seguimiento Diario'!G6 -> 0 | N10: =1740/1581*L10 -> 1189.7154 | O10: =N10/L10*M10 -> 0 | P10: =M10/L10 -> 0
B11: 37573918087 | C11: Electrocaqueta | D11: Santander | E11: Santander | F11: Bolivar, Charalá, El Peñón, Florian, La Belleza, Landazuri, Ocamonte, Simac ota, Sucre, zapatoca | G11: Comunidades Energéticas OR | H11: Individual | I11: =$B$11/1158*L11 -> 2.2713077e+10 | J11: 46184 | K11: Junio | L11: 700 | M11: ='Seguimiento Diario'!F7 -> 0 | N11: =1270/1158*L11 -> 767.70294 | O11: =N11/L11*M11 -> 0 | P11: =M11/L11 -> 0
C12: Electrocaqueta | D12: Santander | E12: Santander | F12: Bolivar, Charalá, El Peñón, Florian, La Belleza, Landazuri, Ocamonte, Simac ota, Sucre, zapatoca | G12: Comunidades Energéticas OR | H12: Individual | I12: =$B$11/1158*L12 -> 1.4860842e+10 | J12: 46228 | K12: Julio | L12: =1158-L11 -> 458 | M12: ='Seguimiento Diario'!G7 -> 0 | N12: =1270/1158*L12 -> 502.29706 | O12: =N12/L12*M12 -> 0 | P12: =M12/L12 -> 0
B13: 4402514558 | C13: Electrocaqueta | D13: Santander | E13: Guaca | F13: Guaca | G13: Comunidades Energéticas OR | H13: Individual | I13: =$B$13/154*L13 -> 2.3727838e+09 | J13: 46184 | K13: Junio | L13: 83 | M13: ='Seguimiento Diario'!F8 -> 0 | N13: =190/154*L13 -> 102.4026 | O13: =N13/L13*M13 -> 0 | P13: =M13/L13 -> 0
C14: Electrocaqueta | D14: Santander | E14: Guaca | F14: Guaca | G14: Comunidades Energéticas OR | H14: Individual | I14: =$B$13/154*L14 -> 2.0297307e+09 | J14: 46228 | K14: Julio | L14: =154-L13 -> 71 | M14: ='Seguimiento Diario'!G8 -> 0 | N14: =190/154*L14 -> 87.597403 | O14: =N14/L14*M14 -> 0 | P14: =M14/L14 -> 0
B15: 27742028640 | C15: Electrocaqueta | D15: Nariño | E15: Ricaurte | F15: Ricaurte | G15: Comunidades Energéticas OR | H15: Individual | I15: =$B$15/862*L15 -> 3.2183328e+08 | J15: 46184 | K15: Junio | L15: 10 | M15: ='Seguimiento Diario'!F9 -> 0 | N15: =950/862*L15 -> 11.020882 | O15: =N15/L15*M15 -> 0 | P15: =M15/L15 -> 0
C16: Electrocaqueta | D16: Nariño | E16: Ricaurte | F16: Ricaurte | G16: Comunidades Energéticas OR | H16: Individual | I16: =$B$15/862*L16 -> 2.7420195e+10 | J16: 46228 | K16: Julio | L16: =862-L15 -> 852 | M16: ='Seguimiento Diario'!G9 -> 0 | N16: =950/862*L16 -> 938.97912 | O16: =N16/L16*M16 -> 0 | P16: =M16/L16 -> 0
C17: Electrocaqueta | D17: Norte de Santander | E17: Norte de Santander | F17: TEORAMA EL CARMEN CONVENCIÓN HACARI SAN CALIXTO TIBU | G17: Comunidades Energéticas OR | H17: Individual | I17: 121589085878 | J17: 46228 | K17: Julio | L17: 3783 | M17: ='Seguimiento Diario'!G10 -> 0 | N17: =4160/3783*L17 -> 4160 | O17: =N17/L17*M17 -> 0 | P17: =M17/L17 -> 0
B18: 322709746890 | C18: Dispac | D18: La Guajira | E18: Maicao y Albania | F18: Maicao y Albania | G18: Comunidades Energéticas OR | H18: Individual | I18: =$B$18/10664*L18 -> 1.2104642e+10 | J18: 46167 | K18: Mayo | L18: 400 | M18: ='Seguimiento Diario'!E11 -> 0 | N18: =11730/10664*L18 -> 439.985 | O18: =N18/L18*M18 -> 0 | P18: =M18/L18 -> 0
C19: Dispac | D19: La Guajira | E19: Maicao y Albania | F19: Maicao y Albania | G19: Comunidades Energéticas OR | H19: Individual | I19: =$B$18/10664*L19 -> 1.2104642e+10 | J19: 46188 | K19: Junio | L19: 400 | M19: ='Seguimiento Diario'!F11 -> 0 | N19: =11730/10664*L19 -> 439.985 | O19: =N19/L19*M19 -> 0 | P19: =M19/L19 -> 0
C20: Dispac | D20: La Guajira | E20: Maicao y Albania | F20: Maicao y Albania | G20: Comunidades Energéticas OR | H20: Individual | I20: =$B$18/10664*L20 -> 2.9850046e+11 | J20: 46228 | K20: Julio | L20: =10664-(L18+L19) -> 9864 | M20: ='Seguimiento Diario'!G11 -> 0 | N20: =11730/10664*L20 -> 10850.03 | O20: =N20/L20*M20 -> 0 | P20: =M20/L20 -> 0
B21: 24437339433 | C21: Gensa | D21: Caqueta | E21: Cartagena del Chaiira | F21: Cartagena del Chaiira | G21: Comunidades Energéticas OR | H21: Individual | I21: =$B$21/755*L21 -> 6.4734674e+09 | J21: 46162 | K21: Mayo | L21: 200 | M21: ='Seguimiento Diario'!E12 -> 0 | N21: =1520/755*L21 -> 402.64901 | O21: =N21/L21*M21 -> 0 | P21: =M21/L21 -> 0
C22: Gensa | D22: Caqueta | E22: Cartagena del Chaiira | F22: Cartagena del Chaiira | G22: Comunidades Energéticas OR | H22: Individual | I22: =$B$21/755*L22 -> 6.4734674e+09 | J22: 46193 | K22: Junio | L22: 200 | M22: ='Seguimiento Diario'!F12 -> 0 | N22: =1520/755*L22 -> 402.64901 | O22: =N22/L22*M22 -> 0 | P22: =M22/L22 -> 0
C23: Gensa | D23: Caqueta | E23: Cartagena del Chaiira | F23: Cartagena del Chaiira | G23: Comunidades Energéticas OR | H23: Individual | I23: =$B$21/755*L23 -> 1.1490405e+10 | J23: 46228 | K23: Julio | L23: =755-(L21+L22) -> 355 | M23: ='Seguimiento Diario'!G12 -> 0 | N23: =1520/755*L23 -> 714.70199 | O23: =N23/L23*M23 -> 0 | P23: =M23/L23 -> 0
B24: 31420264769 | C24: Gensa | D24: Meta | E24: La Uribe | F24: La Uribe | G24: Comunidades Energéticas OR | H24: Individual | I24: =$B$24/1003*L24 -> 6.2652572e+09 | J24: 46172 | K24: Mayo | L24: 200 | M24: ='Seguimiento Diario'!E13 -> 0 | N24: =1210/1003*L24 -> 241.27617 | O24: =N24/L24*M24 -> 0 | P24: =M24/L24 -> 0
C25: Gensa | D25: Meta | E25: La Uribe | F25: La Uribe | G25: Comunidades Energéticas OR | H25: Individual | I25: =$B$24/1003*L25 -> 9.3978858e+09 | J25: 46193 | K25: Junio | L25: 300 | M25: ='Seguimiento Diario'!F13 -> 0 | N25: =1210/1003*L25 -> 361.91426 | O25: =N25/L25*M25 -> 0 | P25: =M25/L25 -> 0
C26: Gensa | D26: Meta | E26: La Uribe | F26: La Uribe | G26: Comunidades Energéticas OR | H26: Individual | I26: =$B$24/1003*L26 -> 1.5757122e+10 | J26: 46228 | K26: Julio | L26: =1003-(L24+L25) -> 503 | M26: ='Seguimiento Diario'!G13 -> 0 | N26: =1210/1003*L26 -> 606.80957 | O26: =N26/L26*M26 -> 0 | P26: =M26/L26 -> 0
B27: 30713269905 | C27: Gensa | D27: La Guajira | E27: Uribia | F27: Uribia | G27: Comunidades Energéticas OR | H27: Individual | I27: =$B$27/1000*L27 -> 3.071327e+09 | J27: 46172 | K27: Mayo | L27: 100 | M27: ='Seguimiento Diario'!E14 -> 0 | N27: =1200/1000*L27 -> 120 | O27: =N27/L27*M27 -> 0 | P27: =M27/L27 -> 0
C28: Gensa | D28: La Guajira | E28: Uribia | F28: Uribia | G28: Comunidades Energéticas OR | H28: Individual | I28: =$B$27/1000*L28 -> 4.6069905e+09 | J28: 46193 | K28: Junio | L28: 150 | M28: ='Seguimiento Diario'!F14 -> 0 | N28: =1200/1000*L28 -> 180 | O28: =N28/L28*M28 -> 0 | P28: =M28/L28 -> 0
C29: Gensa | D29: La Guajira | E29: Uribia | F29: Uribia | G29: Comunidades Energéticas OR | H29: Individual | I29: =$B$27/1000*L29 -> 2.3034952e+10 | J29: 46228 | K29: Julio | L29: =1000-(L27+L28) -> 750 | M29: ='Seguimiento Diario'!G14 -> 0 | N29: =1200/1000*L29 -> 900 | O29: =N29/L29*M29 -> 0 | P29: =M29/L29 -> 0
B30: ='[1]Base Actualizada'!$E$23+'[1]Base Actualizada'!$E$24+'[1]Base Actualizada'!$E$25+'[1]Base Actualizada'!$E$26 -> 63797499014 | C30: Gensa | D30: Putumayo | E30: San Miguel, Valle del Guamuez,Villa Garzon,Puerto Guzman | F30: San Miguel, Valle del Guamuez,Villa Garzon,Puerto Guzman | G30: Comunidades Energéticas OR | H30: Individual | I30: =$B$30/2006*L30 -> 1.2721336e+10 | J30: 46167 | K30: Mayo | L30: 400 | M30: ='Seguimiento Diario'!E15 -> 0 | N30: =2550/2006*L30 -> 508.47458 | O30: =N30/L30*M30 -> 0 | P30: =M30/L30 -> 0
C31: Gensa | D31: Putumayo | E31: San Miguel, Valle del Guamuez,Villa Garzon,Puerto Guzman | F31: San Miguel, Valle del Guamuez,Villa Garzon,Puerto Guzman | G31: Comunidades Energéticas OR | H31: Individual | I31: =$B$30/2006*L31 -> 5.1076163e+10 | J31: 46228 | K31: Julio | L31: =2006-L30 -> 1606 | M31: ='Seguimiento Diario'!G15 -> 0 | N31: =2550/2006*L31 -> 2041.5254 | O31: =N31/L31*M31 -> 0 | P31: =M31/L31 -> 0
C32: Gecelca | D32: Atlantico | E32: Villas de San Pablo | F32: Atlantico | G32: Colombia Solar | H32: Individual | I32: 8256253500 | J32: 46162 | K32: Mayo | L32: 500 | M32: ='Seguimiento Diario'!E16 -> 12 | N32: 750 | O32: =N32/L32*M32 -> 18 | P32: =M32/L32 -> 0.024
C33: Gecelca | D33: Atlantico | E33: Villas de San Pablo | F33: Atlantico | G33: Colombia Solar | H33: Individual | I33: 11278042281 | J33: 46203 | K33: Junio | L33: 683 | M33: ='Seguimiento Diario'!F16 -> 0 | N33: 1229.4 | O33: =N33/L33*M33 -> 0 | P33: =M33/L33 -> 0
C34: Gecelca | D34: Atlantico | E34: Villas de San Pablo | F34: Atlantico | G34: Colombia Solar | H34: Individual | I34: 21746971719 | J34: 46233 | K34: Julio | L34: 1317 | M34: ='Seguimiento Diario'!G16 -> 0 | N34: 2370.6 | O34: =N34/L34*M34 -> 0 | P34: =M34/L34 -> 0
C35: IPSE | D35: La Guajira | E35: MANAURE | F35: MANAURE | G35: IPSE | H35: Individual | I35: 56292206192 | J35: 46149 | K35: Mayo | L35: 1344 | M35: ='Seguimiento Diario'!E17 -> 0 | N35: 1842.5 | O35: =N35/L35*M35 -> 0 | P35: =M35/L35 -> 0
C36: IPSE | D36: Cauca | E36: ARGELIA, PATÍA, PIENDAMÓ, TUNÍA, SOTARÁ | F36: ARGELIA, PATÍA, PIENDAMÓ, TUNÍA, SOTARÁ | G36: IPSE | H36: Individual | I36: 11930657218 | J36: 46163 | K36: Mayo | L36: 376 | M36: ='Seguimiento Diario'!E18 -> 0 | N36: 503.84 | O36: =N36/L36*M36 -> 0 | P36: =M36/L36 -> 0
C37: IPSE | D37: Cauca | E37: GUAPI | F37: GUAPI | G37: IPSE | H37: Individual | I37: 959419512 | J37: 46164 | K37: Mayo | L37: 80 | M37: ='Seguimiento Diario'!E19 -> 0 | N37: 58.08 | O37: =N37/L37*M37 -> 0 | P37: =M37/L37 -> 0
C38: IPSE | D38: Cauca | E38: LOPEZ DE MICAY | F38: LOPEZ DE MICAY | G38: IPSE | H38: Individual | I38: 7817475406 | J38: 46169 | K38: Mayo | L38: 247 | M38: ='Seguimiento Diario'!E20 -> 0 | N38: 330.98 | O38: =N38/L38*M38 -> 0 | P38: =M38/L38 -> 0
C39: IPSE | D39: La Guajira | E39: ALBANIA | F39: ALBANIA | G39: IPSE | H39: Individual | I39: 10294382128 | J39: 46149 | K39: Mayo | L39: 395 | M39: ='Seguimiento Diario'!E21 -> 0 | N39: 323.9 | O39: =N39/L39*M39 -> 0 | P39: =M39/L39 -> 0
C40: IPSE | D40: Vichada | E40: LA PRIMAVERA | F40: LA PRIMAVERA | G40: IPSE | H40: Individual | I40: 7215361382 | J40: 46190 | K40: Junio | L40: 228 | M40: ='Seguimiento Diario'!F22 -> 0 | N40: 250.8 | O40: =N40/L40*M40 -> 0 | P40: =M40/L40 -> 0
C41: FENOGE | D41: Región 2 Caquetá | E41: Florencia | F41: Florencia | G41: Fenoge 1.0 y 1.1 | H41: Centralizadas | I41: 7623200000 | J41: 46203 | K41: Junio | L41: 500 | M41: ='Seguimiento Diario'!F23 -> 0 | N41: 1000 | O41: =N41/L41*M41 -> 0 | P41: =M41/L41 -> 0
...

Sheet TD
A1: MES | B1: (Todas)
A2: PROGRAMA | B2: (Todas)
D4: Valores
A5: CONTRATISTA | B5: PROYECTO | C5: FECHA | D5: Suma de PLANEADO (USUARIOS) | E5: Suma de EJECUTADO (USUARIOS) | F5: Suma de CAPACIDAD (kWp) (PLANEADA) | G5: Suma de CAPACIDAD (kWp) (EJECUTADA) | H5: Suma de EFICIENCIA | I5: Suma de INVERSIÓN
A6: Dispac | B6: Maicao y Albania | C6: 46167 | D6: 400 | E6: 0 | F6: 439.985 | G6: 0 | H6: 0 | I6: 1.2104642e+10
C7: 46228 | D7: 9864 | E7: 0 | F7: 10850.03 | G7: 0 | H7: 0 | I7: 2.9850046e+11
C8: 46188 | D8: 400 | E8: 0 | F8: 439.985 | G8: 0 | H8: 0 | I8: 1.2104642e+10
A9: Total Dispac | D9: 10664 | E9: 0 | F9: 11730 | G9: 0 | H9: 0 | I9: 3.2270975e+11
A10: Electrocaqueta | B10: Becerril | C10: 46162 | D10: 200 | E10: 180 | F10: 243.98074 | G10: 219.58266 | H10: 0.9 | I10: 5.92225e+09
C11: 46184 | D11: 200 | E11: 0 | F11: 243.98074 | G11: 0 | H11: 0 | I11: 5.92225e+09
C12: 46228 | D12: 223 | E12: 0 | F12: 272.03852 | G12: 0 | H12: 0 | I12: 6.6033087e+09
B13: Curumaní | C13: 46162 | D13: 100 | E13: 0 | F13: 121.79487 | G13: 0 | H13: 0 | I13: 2.9029905e+09
C14: 46184 | D14: 150 | E14: 0 | F14: 182.69231 | G14: 0 | H14: 0 | I14: 4.3544858e+09
C15: 46228 | D15: 374 | E15: 0 | F15: 455.51282 | G15: 0 | H15: 0 | I15: 1.0857185e+10
B16: Norte de Santander | C16: 46228 | D16: 3783 | E16: 0 | F16: 4160 | G16: 0 | H16: 0 | I16: 121589085878
B17: Santa Marta | C17: 46184 | D17: 500 | E17: 0 | F17: 550.28463 | G17: 0 | H17: 0 | I17: 1.6156624e+10
C18: 46228 | D18: 1081 | E18: 0 | F18: 1189.7154 | G18: 0 | H18: 0 | I18: 3.4930621e+10
B19: Santander | C19: 46184 | D19: 700 | E19: 0 | F19: 767.70294 | G19: 0 | H19: 0 | I19: 2.2713077e+10
C20: 46228 | D20: 458 | E20: 0 | F20: 502.29706 | G20: 0 | H20: 0 | I20: 1.4860842e+10
B21: Guaca | C21: 46184 | D21: 83 | E21: 0 | F21: 102.4026 | G21: 0 | H21: 0 | I21: 2.3727838e+09
C22: 46228 | D22: 71 | E22: 0 | F22: 87.597403 | G22: 0 | H22: 0 | I22: 2.0297307e+09
B23: Ricaurte | C23: 46184 | D23: 10 | E23: 0 | F23: 11.020882 | G23: 0 | H23: 0 | I23: 3.2183328e+08
C24: 46228 | D24: 852 | E24: 0 | F24: 938.97912 | G24: 0 | H24: 0 | I24: 2.7420195e+10
A25: Total Electrocaqueta | D25: 8785 | E25: 180 | F25: 9830 | G25: 219.58266 | H25: 0.9 | I25: 278957261427
A26: Gensa | B26: Cartagena del Chaiira | C26: 46162 | D26: 200 | E26: 0 | F26: 402.64901 | G26: 0 | H26: 0 | I26: 6.4734674e+09
C27: 46193 | D27: 200 | E27: 0 | F27: 402.64901 | G27: 0 | H27: 0 | I27: 6.4734674e+09
C28: 46228 | D28: 355 | E28: 0 | F28: 714.70199 | G28: 0 | H28: 0 | I28: 1.1490405e+10
B29: La Uribe | C29: 46172 | D29: 200 | E29: 0 | F29: 241.27617 | G29: 0 | H29: 0 | I29: 6.2652572e+09
C30: 46193 | D30: 300 | E30: 0 | F30: 361.91426 | G30: 0 | H30: 0 | I30: 9.3978858e+09
C31: 46228 | D31: 503 | E31: 0 | F31: 606.80957 | G31: 0 | H31: 0 | I31: 1.5757122e+10
B32: San Miguel, Valle del Guamuez,Villa Garzon,Puerto Guzman | C32: 46167 | D32: 400 | E32: 0 | F32: 508.47458 | G32: 0 | H32: 0 | I32: 1.2721336e+10
C33: 46228 | D33: 1606 | E33: 0 | F33: 2041.5254 | G33: 0 | H33: 0 | I33: 5.1076163e+10
B34: Uribia | C34: 46172 | D34: 100 | E34: 0 | F34: 120 | G34: 0 | H34: 0 | I34: 3.071327e+09
C35: 46193 | D35: 150 | E35: 0 | F35: 180 | G35: 0 | H35: 0 | I35: 4.6069905e+09
C36: 46228 | D36: 750 | E36: 0 | F36: 900 | G36: 0 | H36: 0 | I36: 2.3034952e+10
A37: Total Gensa | D37: 4764 | E37: 0 | F37: 6480 | G37: 0 | H37: 0 | I37: 150368373121
A38: Gecelca | B38: Villas de San Pablo | C38: 46162 | D38: 500 | E38: 12 | F38: 750 | G38: 18 | H38: 0.024 | I38: 8256253500
C39: 46203 | D39: 683 | E39: 0 | F39: 1229.4 | G39: 0 | H39: 0 | I39: 11278042281
C40: 46233 | D40: 1317 | E40: 0 | F40: 2370.6 | G40: 0 | H40: 0 | I40: 21746971719
A41: Total Gecelca | D41: 2500 | E41: 12 | F41: 4350 | G41: 18 | H41: 0.024 | I41: 41281267500
...

Sheet Hoja3
A1: Proyecto | B1: (Varios elementos)
A3: Suma de Inversion
A4: Operador de Red | B4: Departamento | C4: Total
A5: DISPAC | B5: La Guajira | C5: 322709746890
A6: Total DISPAC | C6: 322709746890
A7: ELECTROCAQUETA | B7: Cesar | C7: 36562469742
B8: Magdalena | C8: 51087244522
B9: Nariño | C9: 27742028640
B10: Norte de Santander | C10: 121589085878
B11: Santander | C11: 41976432645
A12: Total ELECTROCAQUETA | C12: 278957261427
A13: GECELCA | B13: Atlantico | C13: 41281267500
A14: Total GECELCA | C14: 41281267500
A15: GENSA | B15: Caquetá | C15: 24437339433
B16: La Guajira | C16: 30713269905
B17: Meta | C17: 31420264769
B18: Putumayo | C18: 63797499014
A19: Total GENSA | C19: 150368373121
A20: Total general | C20: 793316648938

Sheet Hoja1
C3: Departamento | D3: Municipio | E3: Operador de Red | F3: Inversion | G3: Potencia a Instalar MWp | H3: Usuarios Totales | I3: Semaforo | J3: Observaciones | O3: Criterio | P3: Rango | Q3: Calculo
C4: La Guajira | D4: Maicao Y Albania | E4: DISPAC | F4: 322709746890 | G4: 11.73 | H4: 10664 | I4: 0.067516879 | K4: =Tabla1[[#This Row],[14/06/2026]]/Tabla1[[#This Row],[Usuarios Totales]] -> 0.067516879 | O4: Rojo | P4: 0.1
C5: Norte de Santander | D5: Teorama, El Carmen, Convención, Hacari, San Calixto, Tibu | E5: ELECTROCAQUETA | F5: 121589085878 | G5: 4.16 | H5: 3783 | I5: 0.042294475 | K5: =Tabla1[[#This Row],[14/06/2026]]/Tabla1[[#This Row],[Usuarios Totales]] -> 0.042294475 | O5: Amarillo | P5: 0.3
C6: Nariño | D6: Ricaurte | E6: ELECTROCAQUETA | F6: 27742028640 | G6: 0.95 | H6: 862 | I6: 0 | K6: =Tabla1[[#This Row],[14/06/2026]]/Tabla1[[#This Row],[Usuarios Totales]] -> 0 | O6: Verde | P6: 0.5
C7: Magdalena | D7: Santa Marta | E7: ELECTROCAQUETA | F7: 51087244522 | G7: 1.74 | H7: 1581 | I7: 0.18722328 | K7: =Tabla1[[#This Row],[14/06/2026]]/Tabla1[[#This Row],[Usuarios Totales]] -> 0.18722328
C8: Santander | D8: Bolivar, Charalá, El Peñón, Florian, La Belleza, Landazuri, Ocamonte, Simacota, Sucre, Zapatoca | E8: ELECTROCAQUETA | F8: 37573918087 | G8: 1.27 | H8: 1158 | I8: 0.10708117 | K8: =Tabla1[[#This Row],[14/06/2026]]/Tabla1[[#This Row],[Usuarios Totales]] -> 0.10708117
C9: Santander | D9: Guaca | E9: ELECTROCAQUETA | F9: 4402514558 | G9: 0.19 | H9: 154 | I9: 0.38961039 | K9: =Tabla1[[#This Row],[14/06/2026]]/Tabla1[[#This Row],[Usuarios Totales]] -> 0.38961039
C10: Meta | D10: La Uribe | E10: GENSA | F10: 31420264769 | G10: 1.21 | H10: 1003 | I10: 0.059820538 | K10: =Tabla1[[#This Row],[14/06/2026]]/Tabla1[[#This Row],[Usuarios Totales]] -> 0.059820538
C11: Cesar | D11: Becerril | E11: ELECTROCAQUETA | F11: 18447808737 | G11: 0.76 | H11: 623 | I11: 0.69020867 | K11: =Tabla1[[#This Row],[14/06/2026]]/Tabla1[[#This Row],[Usuarios Totales]] -> 0.69020867
C12: Cesar | D12: Curumani | E12: ELECTROCAQUETA | F12: 18114661005 | G12: 0.76 | H12: 624 | I12: 0.5 | K12: =Tabla1[[#This Row],[14/06/2026]]/Tabla1[[#This Row],[Usuarios Totales]] -> 0.43269231
C13: La Guajira | D13: Uribia | E13: GENSA | F13: 30713269905 | G13: 1.2 | H13: 1000 | I13: 0.06 | K13: =Tabla1[[#This Row],[14/06/2026]]/Tabla1[[#This Row],[Usuarios Totales]] -> 0.06
C14: Putumayo | D14: San Miguel | E14: GENSA | F14: 6880380834 | G14: 0.31 | H14: 217 | I14: 0.092165899 | K14: =Tabla1[[#This Row],[14/06/2026]]/Tabla1[[#This Row],[Usuarios Totales]] -> 0.092165899
C15: Putumayo | D15: Valle Del Guamuez | E15: GENSA | F15: 22802905997 | G15: 0.72 | H15: 719 | I15: 0.013908206 | K15: =Tabla1[[#This Row],[14/06/2026]]/Tabla1[[#This Row],[Usuarios Totales]] -> 0.013908206
C16: Putumayo | D16: Villa Garzon | E16: GENSA | F16: 9349545113 | G16: 0.42 | H16: 293 | I16: 0.034129693 | K16: =Tabla1[[#This Row],[14/06/2026]]/Tabla1[[#This Row],[Usuarios Totales]] -> 0.034129693
C17: Putumayo | D17: Puerto Guzman | E17: GENSA | F17: 24764667070 | G17: 1.1 | H17: 777 | I17: 0.077220077 | K17: =Tabla1[[#This Row],[14/06/2026]]/Tabla1[[#This Row],[Usuarios Totales]] -> 0.077220077
C18: Caquetá | D18: Cartagena Del Chaira | E18: GENSA | F18: 24437339433 | G18: 1.52 | H18: 755 | I18: 0.046357616 | K18: =Tabla1[[#This Row],[14/06/2026]]/Tabla1[[#This Row],[Usuarios Totales]] -> 0.046357616
C19: Atlantico | D19: Atlantico | E19: GECELCA | F19: 41281267500 | G19: 4.35 | H19: 2500 | I19: 0.2768 | K19: =Tabla1[[#This Row],[14/06/2026]]/Tabla1[[#This Row],[Usuarios Totales]] -> 0.2768
C20: Totales | F20: =SUM(F4:F19) -> 793316648938 | G20: =SUM(G4:G19) -> 32.39 | H20: =SUM(H4:H19) -> 26713

Sheet Proyectado Obras Civiles
A1: Proyecto | B1: Departamento | C1: Municipio | D1: Operador de Red | E1: Inversion | F1: Potencia a Instalar MWp | G1: Usuarios Totales | H1: 05/05/2026 | I1: 10/05/2026 | J1: 15/05/2026 | K1: 20/05/2026 | L1: 25/05/2026 | M1: 30/05/2026 | N1: 04/06/2026 | O1: 09/06/2026 | P1: 14/06/2026 | Q1: 20/06/2026 | R1: 25/06/2026 | S1: 30/06/2026 | T1: 05/07/2026 | U1: 10/07/2026 | V1: 15/07/2026 | W1: 20/07/2026 | X1: 25/07/2026 | Y1: 30/07/2026
A2: Nuqui | B2: Chocó | C2: Nuqui | D2: DISPAC | E2: 79316865070 | F2: 4 | G2: 2036 | H2: 50 | I2: 100 | J2: 150 | K2: 200 | L2: 270 | M2: 320 | N2: 350 | O2: 370 | P2: 380 | Q2: 400 | R2: 900 | S2: 1100 | T2: 1450 | U2: 1650 | V2: 1700 | W2: 1800 | X2: 1900 | Y2: 2036
A3: Bahia Solano | B3: Chocó | C3: Bahia Solano | D3: GENSA | E3: 83008042889 | F3: 3 | G3: 2295 | H3: 20 | I3: =+H3+25 -> 45 | J3: =+I3+70 -> 115 | K3: 200 | L3: 230 | M3: =+L3+10 -> 240 | N3: =+M3+50 -> 290 | O3: =+N3+60 -> 350 | P3: =+O3+20 -> 370 | Q3: 400 | R3: 425 | S3: =+R3+100 -> 525 | T3: =+S3+250 -> 775 | U3: =+T3+250 -> 1025 | V3: =+U3+250 -> 1275 | W3: =+V3+600 -> 1875 | X3: =+W3+100 -> 1975 | Y3: 2295
A4: Maicao Y Albania | B4: La Guajira | C4: Maicao Y Albania | D4: DISPAC | E4: 322709746890 | F4: 11.73 | G4: 10664 | H4: 0 | I4: 0 | J4: 80 | K4: 240 | L4: 400 | M4: 480 | N4: 560 | O4: 640 | P4: 720 | Q4: 800 | R4: 1050 | S4: 1550 | T4: 2350 | U4: 3350 | V4: 4600 | W4: 6100 | X4: 8100 | Y4: 10664
A5: Norte De Santander | B5: Norte de Santander | C5: Teorama, El Carmen, Convención, Hacari, San Calixto, Tibu | D5: ELECTROCAQUETA | E5: 121589085878 | F5: 4.16 | G5: 3783 | H5: 0 | I5: 0 | J5: 0 | K5: 0 | L5: 0 | M5: 0 | N5: 0 | O5: 150 | P5: 160 | Q5: 160 | R5: 160 | S5: 160 | T5: 410 | U5: 660 | V5: 910 | W5: 1510 | X5: 1610 | Y5: 3783
A6: Ricaurte | B6: Nariño | C6: Ricaurte | D6: ELECTROCAQUETA | E6: 27742028640 | F6: 0.95 | G6: 862 | H6: 70 | I6: 95 | J6: 165 | K6: 200 | L6: 250 | M6: 260 | N6: 310 | O6: 370 | P6: 390 | Q6: 400 | R6: 420 | S6: 470 | T6: 570 | U6: 595 | V6: 625 | W6: 650 | X6: 750 | Y6: 862
A7: Santa Marta | B7: Magdalena | C7: Santa Marta | D7: ELECTROCAQUETA | E7: 51087244522 | F7: 1.74 | G7: 1581 | H7: 100 | I7: 125 | J7: 185 | K7: 200 | L7: 220 | M7: 230 | N7: 280 | O7: 340 | P7: 360 | Q7: 400 | R7: 450 | S7: 550 | T7: 650 | U7: 700 | V7: 800 | W7: 1000 | X7: 1100 | Y7: 1581
A8: Santander 11 Municipios | B8: Santander | C8: Bolivar, Charalá, El Peñón, Florian, La Belleza, Landazuri, Ocamonte, Simacota, Sucre, Zapatoca | D8: ELECTROCAQUETA | E8: 37573918087 | F8: 1.27 | G8: 1158 | H8: 20 | I8: 45 | J8: 115 | K8: 200 | L8: 210 | M8: 220 | N8: 270 | O8: 330 | P8: 350 | Q8: 400 | R8: 500 | S8: 550 | T8: 750 | U8: 900 | V8: 960 | W8: 980 | X8: 1080 | Y8: 1158
A9: Santander - Guaca | B9: Santander | C9: Guaca | D9: ELECTROCAQUETA | E9: 4402514558 | F9: 0.19 | G9: 154 | H9: 0 | I9: 0 | J9: 0 | K9: 0 | L9: 0 | M9: 0 | N9: 50 | O9: 83 | P9: 47 | Q9: 50 | R9: 60 | S9: 65 | T9: 70 | U9: 80 | V9: 85 | W9: 90 | X9: 95 | Y9: 154
A10: La Uribe | B10: Meta | C10: La Uribe | D10: GENSA | E10: 31420264769 | F10: 1.21 | G10: 1003 | H10: 60 | I10: =+H10+25 -> 85 | J10: =+I10+70 -> 155 | K10: 200 | L10: 225 | M10: =+L10+10 -> 235 | N10: =+M10+50 -> 285 | O10: =+N10+60 -> 345 | P10: =+O10+20 -> 365 | Q10: 400 | R10: 450 | S10: =+R10+10 -> 460 | T10: =+S10+20 -> 480 | U10: =+T10+100 -> 580 | V10: =+U10+200 -> 780 | W10: =+V10+10 -> 790 | X10: =+W10+20 -> 810 | Y10: 1003
A11: Becerril | B11: Cesar | C11: Becerril | D11: ELECTROCAQUETA | E11: 18447808737 | F11: 0.76 | G11: 623 | H11: 60 | I11: 120 | J11: 180 | K11: 200 | L11: 250 | M11: 300 | N11: 350 | O11: 400 | P11: 430 | Q11: 460 | R11: 500 | S11: 530 | T11: 560 | U11: 580 | V11: 600 | W11: 610 | X11: 623 | Y11: 623
A12: Curumani | B12: Cesar | C12: Curumani | D12: ELECTROCAQUETA | E12: 18114661005 | F12: 0.76 | G12: 624 | H12: 0 | I12: 0 | J12: 0 | K12: 100 | L12: 120 | M12: 150 | N12: 200 | O12: 250 | P12: 270 | Q12: 400 | R12: 410 | S12: 420 | T12: 430 | U12: 480 | V12: 580 | W12: 590 | X12: 610 | Y12: 624
A13: Uribia | B13: La Guajira | C13: Uribia | D13: GENSA | E13: 30713269905 | F13: 1.2 | G13: 1000 | H13: 60 | I13: =+H13+25 -> 85 | J13: =+I13+70 -> 155 | K13: 200 | L13: 210 | M13: =+L13+10 -> 220 | N13: =+M13+50 -> 270 | O13: =+N13+60 -> 330 | P13: =+O13+20 -> 350 | Q13: 400 | R13: 500 | S13: =+R13+10 -> 510 | T13: =+S13+20 -> 530 | U13: =+T13+100 -> 630 | V13: =+U13+200 -> 830 | W13: =+V13+10 -> 840 | X13: =+W13+20 -> 860 | Y13: 1000
A14: San Miguel | B14: Putumayo | C14: San Miguel | D14: GENSA | E14: 6880380834 | F14: 0.31 | G14: 217 | H14: 20 | I14: 35 | J14: 45 | K14: 50 | L14: 60 | M14: 62 | N14: 70 | O14: 75 | P14: =+O14+20 -> 95 | Q14: 110 | R14: 120 | S14: =+R14+10 -> 130 | T14: 150 | U14: 175 | V14: 180 | W14: 185 | X14: 200 | Y14: 217
A15: Valle Del Guamuez | B15: Putumayo | C15: Valle Del Guamuez | D15: GENSA | E15: 22802905997 | F15: 0.72 | G15: 719 | H15: 10 | I15: =+H15+25 -> 35 | J15: =+I15+70 -> 105 | K15: 200 | L15: 220 | M15: =+L15+10 -> 230 | N15: =+M15+50 -> 280 | O15: =+N15+60 -> 340 | P15: =+O15+20 -> 360 | Q15: 400 | R15: 420 | S15: =+R15+10 -> 430 | T15: =+S15+10 -> 440 | U15: =+T15+50 -> 490 | V15: =+U15+110 -> 600 | W15: =+V15+10 -> 610 | X15: =+W15+20 -> 630 | Y15: 719
A16: Villa Garzon | B16: Putumayo | C16: Villa Garzon | D16: GENSA | E16: 9349545113 | F16: 0.42 | G16: 293 | H16: 10 | I16: 20 | J16: 30 | K16: 50 | L16: 60 | M16: =+L16+10 -> 70 | N16: 80 | O16: 85 | P16: 90 | Q16: 100 | R16: 110 | S16: =+R16+10 -> 120 | T16: 130 | U16: 150 | V16: 160 | W16: 180 | X16: 185 | Y16: 293
A17: Puerto Guzman | B17: Putumayo | C17: Puerto Guzman | D17: GENSA | E17: 24764667070 | F17: 1.1 | G17: 777 | H17: 60 | I17: =+H17+25 -> 85 | J17: =+I17+70 -> 155 | K17: 200 | L17: 225 | M17: =+L17+10 -> 235 | N17: =+M17+50 -> 285 | O17: =+N17+60 -> 345 | P17: =+O17+20 -> 365 | Q17: 300 | R17: 320 | S17: =+R17+10 -> 330 | T17: =+S17+10 -> 340 | U17: =+T17+50 -> 390 | V17: =+U17+110 -> 500 | W17: =+V17+10 -> 510 | X17: =+W17+20 -> 530 | Y17: 777
A18: Cartagena Del Chaira | B18: Caquetá | C18: Cartagena Del Chaira | D18: GENSA | E18: 24437339433 | F18: 1.52 | G18: 755 | H18: 35 | I18: =+H18+25 -> 60 | J18: =+I18+70 -> 130 | K18: 200 | L18: 220 | M18: =+L18+10 -> 230 | N18: =+M18+50 -> 280 | O18: =+N18+60 -> 340 | P18: =+O18+20 -> 360 | Q18: 300 | R18: 310 | S18: =+R18+10 -> 320 | T18: =+S18+10 -> 330 | U18: =+T18+50 -> 380 | V18: =+U18+110 -> 490 | W18: =+V18+10 -> 500 | X18: =+W18+20 -> 520 | Y18: 755
A19: Villas de San Pablo | B19: Atlantico | C19: Atlantico | D19: GECELCA | E19: 41281267500 | F19: 4.35 | G19: 2500
A21: TOTALES | E21: =SUM(E2:E20) -> 955641556897 | F21: =SUM(F2:F20) -> 39.39 | G21: =SUM(G2:G20) -> 31044 | H21: =SUM(H2:H20) -> 575 | I21: =SUM(I2:I20) -> 935 | J21: =SUM(J2:J20) -> 1765 | K21: =SUM(K2:K20) -> 2640 | L21: =SUM(L2:L20) -> 3170 | ... Y21: =SUM(Y2:Y20) -> 28544

Sheet Proyectado Internas
A1: Proyecto | B1: Departamento | C1: Municipio | D1: Operador de Red | E1: Inversion | F1: Potencia a Instalar MWp | G1: Usuarios Totales | H1: 05/05/2026 | I1: 10/05/2026 | J1: 15/05/2026 | K1: 20/05/2026 | L1: 25/05/2026 | M1: 30/05/2026 | N1: 04/06/2026 | O1: 09/06/2026 | P1: 14/06/2026 | Q1: 20/06/2026 | R1: 25/06/2026 | S1: 30/06/2026 | T1: 05/07/2026 | U1: 10/07/2026 | V1: 15/07/2026 | W1: 20/07/2026 | X1: 25/07/2026 | Y1: 30/07/2026
A2: Nuqui | B2: Chocó | C2: Nuqui | D2: DISPAC | E2: 79316865070 | F2: 4 | G2: 2036 | H2: 50 | I2: 100 | J2: 150 | K2: 200 | L2: 270 | M2: 320 | N2: 350 | O2: 370 | P2: 380 | Q2: 400 | R2: 900 | S2: 1100 | T2: 1450 | U2: 1650 | V2: 1700 | W2: 1800 | X2: 1900 | Y2: 2036
A3: Bahia Solano | B3: Chocó | C3: Bahia Solano | D3: GENSA | E3: 83008042889 | F3: 3 | G3: 2295 | H3: 20 | I3: =+H3+25 -> 45 | J3: =+I3+70 -> 115 | K3: 200 | L3: 230 | M3: =+L3+10 -> 240 | N3: =+M3+50 -> 290 | O3: =+N3+60 -> 350 | P3: =+O3+20 -> 370 | Q3: 400 | R3: 425 | S3: =+R3+100 -> 525 | T3: =+S3+250 -> 775 | U3: =+T3+250 -> 1025 | V3: =+U3+250 -> 1275 | W3: =+V3+600 -> 1875 | X3: =+W3+100 -> 1975 | Y3: 2295
A4: Maicao Y Albania | B4: La Guajira | C4: Maicao Y Albania | D4: DISPAC | E4: 322709746890 | F4: 11.73 | G4: 10664 | H4: 0 | I4: 0 | J4: 80 | K4: 240 | L4: 400 | M4: 480 | N4: 560 | O4: 640 | P4: 720 | Q4: 800 | R4: 1050 | S4: 1550 | T4: 2350 | U4: 3350 | V4: 4600 | W4: 6100 | X4: 8100 | Y4: 10664
A5: Norte De Santander | B5: Norte de Santander | C5: Teorama, El Carmen, Convención, Hacari, San Calixto, Tibu | D5: ELECTROCAQUETA | E5: 121589085878 | F5: 4.16 | G5: 3783 | H5: 0 | I5: 0 | J5: 0 | K5: 0 | L5: 0 | M5: 0 | N5: 0 | O5: 150 | P5: 160 | Q5: 160 | R5: 160 | S5: 160 | T5: 410 | U5: 660 | V5: 910 | W5: 1510 | X5: 1610 | Y5: 3783
A6: Ricaurte | B6: Nariño | C6: Ricaurte | D6: ELECTROCAQUETA | E6: 27742028640 | F6: 0.95 | G6: 862 | H6: 70 | I6: 95 | J6: 165 | K6: 200 | L6: 250 | M6: 260 | N6: 310 | O6: 370 | P6: 390 | Q6: 400 | R6: 420 | S6: 470 | T6: 570 | U6: 595 | V6: 625 | W6: 650 | X6: 750 | Y6: 862
A7: Santa Marta | B7: Magdalena | C7: Santa Marta | D7: ELECTROCAQUETA | E7: 51087244522 | F7: 1.74 | G7: 1581 | H7: 100 | I7: 125 | J7: 185 | K7: 200 | L7: 220 | M7: 230 | N7: 280 | O7: 340 | P7: 360 | Q7: 400 | R7: 450 | S7: 550 | T7: 650 | U7: 700 | V7: 800 | W7: 1000 | X7: 1100 | Y7: 1581
A8: Santander 11 Municipios | B8: Santander | C8: Bolivar, Charalá, El Peñón, Florian, La Belleza, Landazuri, Ocamonte, Simacota, Sucre, Zapatoca | D8: ELECTROCAQUETA | E8: 37573918087 | F8: 1.27 | G8: 1158 | H8: 20 | I8: 45 | J8: 115 | K8: 200 | L8: 210 | M8: 220 | N8: 270 | O8: 330 | P8: 350 | Q8: 400 | R8: 500 | S8: 550 | T8: 750 | U8: 900 | V8: 960 | W8: 980 | X8: 1080 | Y8: 1158
A9: Santander - Guaca | B9: Santander | C9: Guaca | D9: ELECTROCAQUETA | E9: 4402514558 | F9: 0.19 | G9: 154 | H9: 0 | I9: 0 | J9: 0 | K9: 0 | L9: 0 | M9: 0 | N9: 50 | O9: 83 | P9: 47 | Q9: 50 | R9: 60 | S9: 65 | T9: 70 | U9: 80 | V9: 85 | W9: 90 | X9: 95 | Y9: 154
A10: La Uribe | B10: Meta | C10: La Uribe | D10: GENSA | E10: 31420264769 | F10: 1.21 | G10: 1003 | H10: 60 | I10: =+H10+25 -> 85 | J10: =+I10+70 -> 155 | K10: 200 | L10: 225 | M10: =+L10+10 -> 235 | N10: =+M10+50 -> 285 | O10: =+N10+60 -> 345 | P10: =+O10+20 -> 365 | Q10: 400 | R10: 450 | S10: =+R10+10 -> 460 | T10: =+S10+20 -> 480 | U10: =+T10+100 -> 580 | V10: =+U10+200 -> 780 | W10: =+V10+10 -> 790 | X10: =+W10+20 -> 810 | Y10: 1003
A11: Becerril | B11: Cesar | C11: Becerril | D11: ELECTROCAQUETA | E11: 18447808737 | F11: 0.76 | G11: 623 | H11: 60 | I11: 120 | J11: 180 | K11: 200 | L11: 250 | M11: 300 | N11: 350 | O11: 400 | P11: 430 | Q11: 460 | R11: 500 | S11: 530 | T11: 560 | U11: 580 | V11: 600 | W11: 610 | X11: 623 | Y11: 623
A12: Curumani | B12: Cesar | C12: Curumani | D12: ELECTROCAQUETA | E12: 18114661005 | F12: 0.76 | G12: 624 | H12: 0 | I12: 0 | J12: 0 | K12: 100 | L12: 120 | M12: 150 | N12: 200 | O12: 250 | P12: 270 | Q12: 400 | R12: 410 | S12: 420 | T12: 430 | U12: 480 | V12: 580 | W12: 590 | X12: 610 | Y12: 624
A13: Uribia | B13: La Guajira | C13: Uribia | D13: GENSA | E13: 30713269905 | F13: 1.2 | G13: 1000 | H13: 60 | I13: =+H13+25 -> 85 | J13: =+I13+70 -> 155 | K13: 200 | L13: 210 | M13: =+L13+10 -> 220 | N13: =+M13+50 -> 270 | O13: =+N13+60 -> 330 | P13: =+O13+20 -> 350 | Q13: 400 | R13: 500 | S13: =+R13+10 -> 510 | T13: =+S13+20 -> 530 | U13: =+T13+100 -> 630 | V13: =+U13+200 -> 830 | W13: =+V13+10 -> 840 | X13: =+W13+20 -> 860 | Y13: 1000
A14: San Miguel | B14: Putumayo | C14: San Miguel | D14: GENSA | E14: 6880380834 | F14: 0.31 | G14: 217 | H14: 20 | I14: 35 | J14: 45 | K14: 50 | L14: 60 | M14: 62 | N14: 70 | O14: 75 | P14: =+O14+20 -> 95 | Q14: 110 | R14: 120 | S14: =+R14+10 -> 130 | T14: 150 | U14: 175 | V14: 180 | W14: 185 | X14: 200 | Y14: 217
A15: Valle Del Guamuez | B15: Putumayo | C15: Valle Del Guamuez | D15: GENSA | E15: 22802905997 | F15: 0.72 | G15: 719 | H15: 10 | I15: =+H15+25 -> 35 | J15: =+I15+70 -> 105 | K15: 200 | L15: 220 | M15: =+L15+10 -> 230 | N15: =+M15+50 -> 280 | O15: =+N15+60 -> 340 | P15: =+O15+20 -> 360 | Q15: 400 | R15: 420 | S15: =+R15+10 -> 430 | T15: =+S15+10 -> 440 | U15: =+T15+50 -> 490 | V15: =+U15+110 -> 600 | W15: =+V15+10 -> 610 | X15: =+W15+20 -> 630 | Y15: 719
A16: Villa Garzon | B16: Putumayo | C16: Villa Garzon | D16: GENSA | E16: 9349545113 | F16: 0.42 | G16: 293 | H16: 10 | I16: 20 | J16: 30 | K16: 50 | L16: 60 | M16: =+L16+10 -> 70 | N16: 80 | O16: 85 | P16: 90 | Q16: 100 | R16: 110 | S16: =+R16+10 -> 120 | T16: 130 | U16: 150 | V16: 160 | W16: 180 | X16: 185 | Y16: 293
A17: Puerto Guzman | B17: Putumayo | C17: Puerto Guzman | D17: GENSA | E17: 24764667070 | F17: 1.1 | G17: 777 | H17: 60 | I17: =+H17+25 -> 85 | J17: =+I17+70 -> 155 | K17: 200 | L17: 225 | M17: =+L17+10 -> 235 | N17: =+M17+50 -> 285 | O17: =+N17+60 -> 345 | P17: =+O17+20 -> 365 | Q17: 300 | R17: 320 | S17: =+R17+10 -> 330 | T17: =+S17+10 -> 340 | U17: =+T17+50 -> 390 | V17: =+U17+110 -> 500 | W17: =+V17+10 -> 510 | X17: =+W17+20 -> 530 | Y17: 777
A18: Cartagena Del Chaira | B18: Caquetá | C18: Cartagena Del Chaira | D18: GENSA | E18: 24437339433 | F18: 1.52 | G18: 755 | H18: 35 | I18: =+H18+25 -> 60 | J18: =+I18+70 -> 130 | K18: 200 | L18: 220 | M18: =+L18+10 -> 230 | N18: =+M18+50 -> 280 | O18: =+N18+60 -> 340 | P18: =+O18+20 -> 360 | Q18: 300 | R18: 310 | S18: =+R18+10 -> 320 | T18: =+S18+10 -> 330 | U18: =+T18+50 -> 380 | V18: =+U18+110 -> 490 | W18: =+V18+10 -> 500 | X18: =+W18+20 -> 520 | Y18: 755
A19: Villas de San Pablo | B19: Atlantico | C19: Atlantico | D19: GECELCA | E19: 41281267500 | F19: 4.35 | G19: 2500
A21: TOTALES | E21: =SUM(E2:E20) -> 955641556897 | F21: =SUM(F2:F20) -> 39.39 | G21: =SUM(G2:G20) -> 31044 | H21: =SUM(H2:H20) -> 575 | I21: =SUM(I2:I20) -> 935 | J21: =SUM(J2:J20) -> 1765 | K21: =SUM(K2:K20) -> 2640 | L21: =SUM(L2:L20) -> 3170 | ... Y21: =SUM(Y2:Y20) -> 28544

Sheet Proyectado Usuarios
A1: Proyecto | B1: Departamento | C1: Municipio | D1: Operador de Red | E1: Inversion | F1: Potencia a Instalar MWp | G1: Usuarios Totales | H1: 05/05/2026 | I1: 10/05/2026 | J1: 15/05/2026 | K1: 20/05/2026 | L1: 25/05/2026 | M1: 30/05/2026 | N1: 04/06/2026 | O1: 09/06/2026 | P1: 14/06/2026 | Q1: 20/06/2026 | R1: 25/06/2026 | S1: 30/06/2026 | T1: 05/07/2026 | U1: 10/07/2026 | V1: 15/07/2026 | W1: 20/07/2026 | X1: 25/07/2026 | Y1: 30/07/2026 | Z1: 05/08/2026 | AA1: 10/08/2026 | AB1: 15/08/2026 | AC1: 20/08/2026 | AD1: 25/08/2026 | AE1: 30/08/2026 | AF1: 5/09/2026 | AG1: 10/09/2026
A2: Nuqui | B2: Chocó | C2: Nuqui | D2: DISPAC | E2: 79316865070 | F2: 4 | G2: 2036 | H2: 50 | I2: 100 | J2: 150 | K2: 200 | L2: 270 | M2: 320 | N2: 350 | O2: 370 | P2: 380 | Q2: 400 | R2: 900 | S2: 1100 | T2: 1450 | U2: 1650 | V2: 1700 | W2: 1800 | X2: 1900 | Y2: 2036
A3: Bahia Solano | B3: Chocó | C3: Bahia Solano | D3: GENSA | E3: 83008042889 | F3: 3 | G3: 2295 | H3: 0 | P3: 20 | Q3: 45 | R3: 115 | S3: 200 | T3: 230 | U3: 240 | V3: 290 | W3: 350 | X3: 370 | Y3: 400 | Z3: 425 | AA3: 525 | AB3: 775 | AC3: 1025 | AD3: 1275 | AE3: 1875 | AF3: 1975 | AG3: 2295
A4: Maicao Y Albania | B4: La Guajira | C4: Maicao Y Albania | D4: DISPAC | E4: 322709746890 | F4: 11.73 | G4: 10664 | H4: 0 | I4: 0 | J4: 80 | K4: 240 | L4: 400 | M4: 480 | N4: 560 | O4: 640 | P4: 720 | Q4: 800 | R4: 960 | S4: 1200 | T4: 1350 | U4: =Tabla1[[#This Row],[05/07/2026]]+800 -> 2150 | V4: =Tabla1[[#This Row],[10/07/2026]]+800 -> 2950 | W4: =Tabla1[[#This Row],[15/07/2026]]+800 -> 3750 | X4: =Tabla1[[#This Row],[20/07/2026]]+800 -> 4550 | Y4: =Tabla1[[#This Row],[25/07/2026]]+800 -> 5350 | Z4: =Tabla1[[#This Row],[30/07/2026]]+800 -> 6150 | AA4: =Tabla1[[#This Row],[05/08/2026]]+800 -> 6950 | AB4: =Tabla1[[#This Row],[10/08/2026]]+800 -> 7750 | AC4: =Tabla1[[#This Row],[15/08/2026]]+800 -> 8550 | AD4: =Tabla1[[#This Row],[20/08/2026]]+800 -> 9350 | AE4: 9800 | AF4: 10230 | AG4: 10664
A5: Norte De Santander | B5: Norte de Santander | C5: Teorama, El Carmen, Convención, Hacari, San Calixto, Tibu | D5: ELECTROCAQUETA | E5: 121589085878 | F5: 4.16 | G5: 3783 | H5: 0 | I5: 0 | J5: 0 | K5: 0 | L5: 0 | M5: 40 | N5: 100 | O5: 160 | P5: 160 | Q5: 160 | R5: 352 | S5: 544 | T5: 736 | U5: 976 | V5: 1168 | W5: 1360 | X5: 1600 | Y5: 1792 | Z5: 2032 | AA5: 2224 | AB5: 2464 | AC5: 2656 | AD5: 2856 | AE5: 3056 | AF5: 3306 | AG5: 3783
A6: Ricaurte | B6: Nariño | C6: Ricaurte | D6: ELECTROCAQUETA | E6: 27742028640 | F6: 0.95 | G6: 862 | H6: 0 | I6: 0 | J6: 0 | K6: 0 | L6: 0 | M6: 0 | N6: 0 | O6: 0 | P6: 0 | Q6: 48 | R6: 84 | S6: 84 | T6: 144 | U6: 232 | V6: 342 | W6: 430 | X6: 518 | Y6: 628 | Z6: 716 | AA6: 862
A7: Santa Marta | B7: Magdalena | C7: Santa Marta | D7: ELECTROCAQUETA | E7: 51087244522 | F7: 1.74 | G7: 1581 | H7: 0 | I7: 0 | J7: 0 | K7: 0 | L7: 0 | M7: 24 | N7: 120 | O7: 208 | P7: 296 | Q7: 416 | R7: 512 | S7: 512 | T7: 624 | U7: 728 | V7: 863 | W7: 983 | X7: 1103 | Y7: 1253 | Z7: 1333 | AA7: 1581
A8: Santander 11 Municipios | B8: Santander | C8: Bolivar, Charalá, El Peñón, Florian, La Belleza, Landazuri, Ocamonte, Simacota, Sucre, Zapatoca | D8: ELECTROCAQUETA | E8: 37573918087 | F8: 1.27 | G8: 1158 | H8: 0 | I8: 0 | J8: 0 | K8: 0 | L8: 0 | M8: 0 | N8: 36 | O8: 76 | P8: 124 | Q8: 194 | R8: 258 | S8: 258 | T8: 322 | U8: 410 | V8: 520 | W8: 608 | X8: 696 | Y8: 806 | Z8: 894 | AA8: 1158
A9: Santander - Guaca | B9: Santander | C9: Guaca | D9: ELECTROCAQUETA | E9: 4402514558 | F9: 0.19 | G9: 154 | H9: 0 | I9: 0 | J9: 0 | K9: 0 | L9: 0 | M9: 0 | N9: 24 | O9: 42 | P9: 60 | Q9: 90 | R9: 114 | S9: 114 | T9: 154
A10: La Uribe | B10: Meta | C10: La Uribe | D10: GENSA | E10: 31420264769 | F10: 1.21 | G10: 1003 | P10: 60 | Q10: 85 | R10: 155 | S10: 200 | T10: 225 | U10: 235 | V10: 285 | W10: 345 | X10: 365 | Y10: 400 | Z10: 450 | AA10: 460 | AB10: 480 | AC10: 580 | AD10: 780 | AE10: 790 | AF10: 810 | AG10: 1003
A11: Becerril | B11: Cesar | C11: Becerril | D11: ELECTROCAQUETA | E11: 18447808737 | F11: 0.76 | G11: 623 | H11: 60 | I11: 120 | J11: 180 | K11: 200 | L11: 250 | M11: 300 | N11: 350 | O11: 400 | P11: 430 | Q11: 460 | R11: 500 | S11: 530 | T11: 560 | U11: 580 | V11: 600 | W11: 610 | X11: 623
A12: Curumani | B12: Cesar | C12: Curumani | D12: ELECTROCAQUETA | E12: 18114661005 | F12: 0.76 | G12: 624 | H12: 0 | I12: 0 | J12: 0 | K12: 100 | L12: 100 | M12: 100 | N12: 125 | O12: 230 | P12: 270 | Q12: 350 | R12: 440 | S12: 510 | T12: 550 | U12: 590 | V12: 620 | W12: 624 | X12: 624
A13: Uribia | B13: La Guajira | C13: Uribia | D13: GENSA | E13: 30713269905 | F13: 1.2 | G13: 1000 | H13: 0 | I13: 0 | J13: 0 | K13: 0 | L13: 0 | M13: 0 | N13: 0 | O13: 0 | P13: 60 | Q13: 85 | R13: 155 | S13: 200 | T13: 210 | U13: 220 | V13: 270 | W13: 330 | X13: 350 | Y13: 400 | Z13: 500 | AA13: 510 | AB13: 530 | AC13: 630 | AD13: 830 | AE13: 840 | AF13: 860 | AG13: 1000
A14: San Miguel | B14: Putumayo | C14: San Miguel | D14: GENSA | E14: 6880380834 | F14: 0.31 | G14: 217 | H14: 0 | I14: 0 | J14: 0 | K14: 0 | L14: 0 | M14: 0 | N14: 0 | O14: 0 | P14: 20 | Q14: 35 | R14: 45 | S14: 50 | T14: 60 | U14: 62 | V14: 70 | W14: 75 | X14: 95 | Y14: 110 | Z14: 120 | AA14: 130 | AB14: 150 | AC14: 175 | AD14: 180 | AE14: 185 | AF14: 200 | AG14: 217
A15: Valle Del Guamuez | B15: Putumayo | C15: Valle Del Guamuez | D15: GENSA | E15: 22802905997 | F15: 0.72 | G15: 719 | H15: 0 | I15: 0 | J15: 0 | K15: 0 | L15: 0 | M15: 0 | N15: 0 | O15: 0 | P15: 10 | Q15: 35 | R15: 105 | S15: 200 | T15: 220 | U15: 230 | V15: 280 | W15: 340 | X15: 360 | Y15: 400 | Z15: 420 | AA15: 430 | AB15: 440 | AC15: 490 | AD15: 600 | AE15: 610 | AF15: 630 | AG15: 719
A16: Villa Garzon | B16: Putumayo | C16: Villa Garzon | D16: GENSA | E16: 9349545113 | F16: 0.42 | G16: 293 | H16: 0 | I16: 0 | J16: 0 | K16: 0 | L16: 0 | M16: 0 | N16: 0 | O16: 0 | P16: 10 | Q16: 20 | R16: 30 | S16: 50 | T16: 60 | U16: 70 | V16: 80 | W16: 85 | X16: 90 | Y16: 100 | Z16: 110 | AA16: 120 | AB16: 130 | AC16: 150 | AD16: 160 | AE16: 180 | AF16: 185 | AG16: 293
A17: Puerto Guzman | B17: Putumayo | C17: Puerto Guzman | D17: GENSA | E17: 24764667070 | F17: 1.1 | G17: 777 | H17: 0 | I17: 0 | J17: 0 | K17: 0 | L17: 0 | M17: 0 | N17: 0 | O17: 0 | P17: 60 | Q17: 85 | R17: 155 | S17: 200 | T17: 225 | U17: 235 | V17: 285 | W17: 345 | X17: 365 | Y17: 300 | Z17: 320 | AA17: 330 | AB17: 340 | AC17: 390 | AD17: 500 | AE17: 510 | AF17: 530 | AG17: 777
A18: Cartagena Del Chaira | B18: Caquetá | C18: Cartagena Del Chaira | D18: GENSA | E18: 24437339433 | F18: 1.52 | G18: 755 | H18: 0 | I18: 0 | J18: 0 | K18: 0 | L18: 0 | M18: 0 | N18: 0 | O18: 0 | P18: 35 | Q18: 60 | R18: 130 | S18: 200 | T18: 220 | U18: 230 | V18: 280 | W18: 340 | X18: 360 | Y18: 300 | Z18: 310 | AA18: 320 | AB18: 330 | AC18: 380 | AD18: 490 | AE18: 500 | AF18: 520 | AG18: 755
A19: Villas de San Pablo | B19: Atlantico | C19: Atlantico | D19: GECELCA | E19: 41281267500 | F19: 4.35 | G19: 2500 | H19: 0 | I19: 0 | J19: 0 | K19: 0 | L19: 100 | M19: 512 | N19: =Tabla1[[#This Row],[30/05/2026]]+60 -> 572 | O19: =Tabla1[[#This Row],[04/06/2026]]+60 -> 632 | P19: =Tabla1[[#This Row],[09/06/2026]]+60 -> 692 | Q19: =Tabla1[[#This Row],[14/06/2026]]+120 -> 812 | R19: =Tabla1[[#This Row],[20/06/2026]]+120 -> 932 | S19: =Tabla1[[#This Row],[25/06/2026]]+120 -> 1052 | T19: 1200 | U19: 1420 | V19: 1720 | W19: 1920 | X19: 2120 | Y19: 2320 | Z19: 2500
A21: TOTALES | E21: =SUM(E2:E20) -> 955641556897 | F21: =SUM(F2:F20) -> 39.39 | G21: =SUM(G2:G20) -> 31044 | H21: =SUM(H2:H20) -> 110 | I21: =SUM(I2:I20) -> 220 | J21: =SUM(J2:J20) -> 410 | K21: =SUM(K2:K20) -> 740 | L21: =SUM(L2:L20) -> 1120 | ... AG21: =SUM(AG2:AG20) -> 21506
G27: ELECTROCAQUETA | H27: 05/05/2026 | I27: 10/05/2026 | J27: 15/05/2026 | K27: 20/05/2026 | L27: 25/05/2026 | M27: 30/05/2026 | N27: 04/06/2026 | O27: 09/06/2026 | P27: 14/06/2026 | Q27: 20/06/2026 | R27: 25/06/2026 | S27: 30/06/2026 | T27: 05/07/2026 | U27: 10/07/2026 | V27: 15/07/2026 | W27: 20/07/2026 | X27: 25/07/2026 | Y27: 30/07/2026 | Z27: 05/08/2026 | AA27: 10/08/2026 | AB27: 15/08/2026 | AC27: 20/08/2026 | AD27: 25/08/2026 | AE27: 30/08/2026 | AF27: 5/09/2026 | AG27: 10/09/2026
G28: =A5 -> Norte De Santander | H28: =H5 -> 0 | I28: =I5-H5 -> 0 | J28: =J5-I5 -> 0 | K28: =K5-J5 -> 0 | L28: =L5-K5 -> 0 | M28: =M5-L5 -> 40 | N28: =N5-M5 -> 60 | O28: =O5-N5 -> 60 | P28: =P5-O5 -> 0 | ... AG28: =AG5-AF5 -> 477
G29: =A6 -> Ricaurte | H29: =H6 -> 0 | I29: =I6-H6 -> 0 | J29: =J6-I6 -> 0 | K29: =K6-J6 -> 0 | L29: =L6-K6 -> 0 | M29: =M6-L6 -> 0 | N29: =N6-M6 -> 0 | O29: =O6-N6 -> 0 | P29: =P6-O6 -> 0 | ... AA29: =AA6-Z6 -> 146 | AC29: =AC6-AB6 -> 0 | AD29: =AD6-AC6 -> 0 | AE29: =AE6-AD6 -> 0 | AF29: =AF6-AE6 -> 0 | AG29: =AG6-AF6 -> 0
G30: =A7 -> Santa Marta | H30: =H7 -> 0 | I30: =I7-H7 -> 0 | J30: =J7-I7 -> 0 | K30: =K7-J7 -> 0 | L30: =L7-K7 -> 0 | M30: =M7-L7 -> 24 | N30: =N7-M7 -> 96 | O30: =O7-N7 -> 88 | P30: =P7-O7 -> 88 | ... AA30: =AA7-Z7 -> 248 | AC30: =AC7-AB7 -> 0 | AD30: =AD7-AC7 -> 0 | AE30: =AE7-AD7 -> 0 | AF30: =AF7-AE7 -> 0 | AG30: =AG7-AF7 -> 0
G31: =A8 -> Santander 11 Municipios | H31: =H8 -> 0 | I31: =I8-H8 -> 0 | J31: =J8-I8 -> 0 | K31: =K8-J8 -> 0 | L31: =L8-K8 -> 0 | M31: =M8-L8 -> 0 | N31: =N8-M8 -> 36 | O31: =O8-N8 -> 40 | P31: =P8-O8 -> 48 | ... AA31: =AA8-Z8 -> 264 | AC31: =AC8-AB8 -> 0 | AD31: =AD8-AC8 -> 0 | AE31: =AE8-AD8 -> 0 | AF31: =AF8-AE8 -> 0 | AG31: =AG8-AF8 -> 0
G32: =A9 -> Santander - Guaca | H32: =H9 -> 0 | I32: =I9-H9 -> 0 | J32: =J9-I9 -> 0 | K32: =K9-J9 -> 0 | L32: =L9-K9 -> 0 | M32: =M9-L9 -> 0 | N32: =N9-M9 -> 24 | O32: =O9-N9 -> 18 | P32: =P9-O9 -> 18 | ... T32: =T9-S9 -> 40 | V32: =V9-U9 -> 0 | W32: =W9-V9 -> 0 | X32: =X9-W9 -> 0 | Y32: =Y9-X9 -> 0 | Z32: =Z9-Y9 -> 0 | AA32: =AA9-Z9 -> 0 | AB32: =AB9-AA9 -> 0 | AC32: =AC9-AB9 -> 0 | ... AG32: =AG9-AF9 -> 0
G33: Becerril | H33: =H11 -> 60 | I33: =I11-H11 -> 60 | J33: =J11-I11 -> 60 | K33: =K11-J11 -> 20 | L33: =L11-K11 -> 50 | M33: =M11-L11 -> 50 | N33: =N11-M11 -> 50 | O33: =O11-N11 -> 50 | P33: =P11-O11 -> 30 | ... X33: =X11-W11 -> 13 | AA33: =AA10-Z10 -> 10 | AB33: =AB10-AA10 -> 20 | AC33: =AC10-AB10 -> 100 | AD33: =AD10-AC10 -> 200 | AE33: =AE10-AD10 -> 10 | AF33: =AF10-AE10 -> 20 | AG33: =AG10-AF10 -> 193
